Workbook

Sheet Read me
A1: SocialUs screen inventory — 2026-10-01
A2: Source: socialus-web origin/main @ b362559 (read via git archive; working tree untouched). Production: www.socialus.org, signed out, measured at 360/390/768/1024/1280/1440/1920 px.
A3: Source column: "Code + verified in prod" = seen on production signed out. "Code" = read from code only (signed-in, owner, operator and overlay states need a sign-in).
A4: Owner view of a Page is not re-inventoried here: see owner-page-spec.md in this folder.
A5: Nothing is marked as cut. Orphaned/unrouted components are listed so every screen is accounted for, not as a recommendation.
A6: Screen sizes: 6" phone ≈ 360–430 css px · 8–11" tablet ≈ 768–1024 · 13–14" laptop ≈ 1280–1440 · 15–16" laptop ≈ 1440–1728 · 27" monitor ≈ 1920–2560.
A7: Tabs: Screens · Counts · Screen sizes · Top problems · Shared UI · Tokens · Token usage · Breakpoints · Deviations · Prod checks

Sheet Screens
A1: ID | B1: Route | C1: Screen | D1: Area | E1: Kind | F1: Host screen | G1: Screen type | H1: Who sees it | I1: Purpose | J1: Sections & controls (top to bottom) | K1: Phone layout (6") | L1: Wide layout (13–27") | M1: Breakpoints used | N1: Structure problems | O1: Files | P1: Source | Q1: Production notes
A2: S001 | B2: (any) | C2: Global not-found | D2: Public browse & detail | E2: error | G2: empty/error | H2: signed out, signed in | I2: Fallback for every notFound() above and any thrown server error | J2: Next.js built-in 404 / error page inside root layout (nav still rendered) | K2: partial | L2: partial | M2: none | N2: • No branded 404/error/loading files anywhere under src/app - every notFound() path and server error falls to framework defaults with no way back except nav | O2: (none) - no src/app/not-found.tsx, error.tsx, loading.tsx or global-error.tsx exist | P2: Code + verified in prod | Q2: Verified: Next default "404 This page could not be found." inside app nav
A3: S002 | B3: (unrouted) HomeFeed | C3: Home feed (orphaned) | D3: Public browse & detail | E3: page | G3: feed | H3: signed out, signed in | I3: Former home: events in next 30 days with filter chips - not imported by any route | J3: Mobile sticky header (logo | You or AuthCtaButtons) > fixed bottom search pill (md:hidden) > H1 'What's on near X' > filter chips All/Markets/Vendor Specials > event grid 2/3 cols (skeleton, empty) > RecruitmentGrid | K3: yes | L3: partial - md:grid-cols-3, no max-w | M3: md: | N3: • Dead code: no import of HomeFeed in src/app (grep) - and it POSTs /api/jobs/generate-market-sessions on mount (HomeFeed.tsx:42) • Uses filter pills, which Explore ruled out (BrowseSurface.tsx:7-9) | O3: src/components/HomeFeed.tsx:31-209 | P3: Code
A4: S003 | B4: (unrouted) LocalityFeed | C4: Locality feed (orphaned) | D4: Public browse & detail | E4: page | G4: feed | H4: signed out, signed in | I4: Place-scoped item feed kept for future; not rendered by any route | J4: MakeThisYoursBanner > 'Near {place}' + ScopePicker select > ItemFeedCard grid 2/3 cols or FeedEmptyState | K4: yes | L4: partial - max-w-3xl, sm:grid-cols-3 | M4: sm: | N4: • ScopePicker pushes '/?place=' (ScopePicker.tsx:27) which now redirects to /explore and drops the param - broken if re-mounted | O4: src/components/feed/LocalityFeed.tsx:15-96; src/components/feed/ScopePicker.tsx | P4: Code
A5: S004 | B5: (unrouted) LocalityFeed | C5: Locality feed - no place | D5: Public browse & detail | E5: empty | F5: (unrouted) LocalityFeed | G5: empty/error | H5: signed out, signed in | I5: 'Where are you?' card | J5: Banner > 'Where are you?' card with no control | K5: yes | L5: partial | M5: none | N5: • Says 'Pick a Place' but offers no picker - dead end (LocalityFeed.tsx:50-53) | O5: src/components/feed/LocalityFeed.tsx:46-56 | P5: Code
A6: S005 | B6: (unrouted) LocalityFeed | C6: Feed empty state | D6: Public browse & detail | E6: empty | F6: (unrouted) LocalityFeed | G6: empty/error | H6: signed out, signed in | I6: No items in locality, widen links | J6: H3 'No matches near you yet.' > hint > 'Widen to X' / 'Any Place in your state' | K6: yes | L6: partial | M6: none | N6: • Links target '/?place=' and '/?widen=state' (FeedEmptyState.tsx:20,27) which redirect to /explore and lose the param | O6: src/components/feed/FeedEmptyState.tsx:3-31 | P6: Code
A7: S006 | B7: (unrouted) RecruitmentGrid | C7: Recruitment grid (orphaned) | D7: Public browse & detail | E7: state | F7: (unrouted) HomeFeed | G7: browse/list+map | H7: signed out, signed in | I7: 'We're looking for makers in Sacramento' open-spot cards; only rendered by orphaned HomeFeed | J7: H2 'We're looking for makers in Sacramento' > featured example card > 'Open spots by category' bouncing chevron > 10 category rows each a horizontal scroller of open-spot + example cards | K7: yes | L7: partial - md: featured card side-by-side; rows always horizontal scrollers | M7: md: | N7: • Hard-coded 'Sacramento' (RecruitmentGrid.tsx:84,165) • Raw amber-*/neutral-* (RecruitmentGrid.tsx:100,103,123,127) • Unreachable (only caller HomeFeed is unrouted) | O7: src/components/RecruitmentGrid.tsx:161-201 | P7: Code
A8: S007 | B8: / | C8: Root redirect | D8: Public browse & detail | E8: redirect | G8: redirect/system | H8: signed out, signed in | I8: Home is paused; always redirects to /explore | J8: redirect('/explore') - nothing renders | K8: n/a | L8: n/a | M8: none | N8: • TopNavDesktop logo links to '/' (BottomNav.tsx:135), costing a redirect hop on every logo click instead of linking /explore • FeedEmptyState/ScopePicker still push '/?place=' and '/?widen=state' (FeedEmptyState.tsx:20,27; ScopePicker.tsx:27); the redirect drops those params | O8: src/app/page.tsx:17-19 | P8: Code + verified in prod | Q8: Verified: / redirects to /explore
A9: S008 | B9: /explore | C9: Explore / Browse (signed out) | D9: Public browse & detail | E9: page | G9: browse/list+map | H9: signed out | I9: Discover Pages and announcements in the current metro; signed-out sees Pages plus withheld announcement cards | J9: Sticky search row (sticky y, top-0 / md:top-14): Area pill (opens ScopeSheet) | Search icon toggle | Filter icon w/ active dot > 'Make this yours' banner (Sign in -> /auth/login?next=/onboarding) > sr-only live region > Result count ('N results match "q"') > CardGrid: first 4 result cards > inline List/Map toggle (NOT sticky, scrolls away) > remaining result cards (Page tiles + withheld announcement cards each with 'Sign up to see what's happening' CTA) | K9: yes - single/2-col auto-fill grid, sticky search row, bottom nav; padding-bottom reserves --nav-height | L9: partial - search row is mx-auto max-w-5xl (1024px) but results section and banner have NO max-width: CardGrid auto-fill minmax(min(100%,14rem),1fr) gives ~4 cols at 1024, ~5 at 1280, ~7+ at 1920, so results run wider than the search row above them; nothing side-by-side (map is a separate view, no list+map split at any width); top nav appears at md (768) | M9: md: (ExploreSearchBar md:top-14 md:px-6; BrowseSurface md:px-6 md:pb-24); sm: in ScopeSheet; no lg:/xl: | N9: • src/components/browse/BrowseSurface.tsx:184 MakeThisYoursBanner rendered as a bare child of <main> with no px wrapper or max-w, so the card sits edge-to-edge while every other section is px-3/md:px-6 inset • Two different sign-up CTAs on the same screen for the same action with different verbs: banner 'Sign in' (MakeThisYoursBanner.tsx:17-19) vs each withheld card 'Sign up to see what's happening' (WithheldAnnouncementCard.tsx:84, lib/copy.ts:12) - both go to /auth/login; plus every withheld card is an accent-filled button, so N primaries in the grid • List/Map toggle is not sticky and is injected after card 4 (src/components/browse/BrowseSurface.tsx:50,256-258); once scrolled past it there is no way to switch to Map without scrolling back. Comment says 4 'completes a row at both 2 and 4 columns' but CardGrid is auto-fill (CardGrid.tsx:48) so at 3/5/6 columns the toggle breaks a half-filled row • ExploreSearchBar is max-w-5xl (ExploreSearchBar.tsx:64,120) while results below are unconstrained - misaligned edges above 1024px • Raw neutral-* colours mixed with tokens: result count text-neutral-600 (BrowseSurface.tsx:211), area pill bg-neutral-100 (ExploreSearchBar.tsx:81), input border-neutral-300 (ExploreSearchBar.tsx:138) • Inconsistent naming of the place concept: pill aria 'Area: X', sheet 'Choose your area', region 'Results in X', banner 'home locality' (MakeThisYoursBanner.tsx:14), metro elsewhere | O9: src/app/explore/page.tsx:20-33; src/app/explore/load.ts:56-148; src/components/browse/BrowseSurface.tsx:168-298; src/components/explore/ExploreSearchBar.tsx:59-152; src/components/feed/MakeThisYoursBanner.tsx; src/components/browse/BrowseResultCard.tsx; src/components/browse/WithheldAnnouncementCard.tsx; src/components/cards/CardGrid.tsx | P9: Code + verified in prod | Q9: Verified 360–1920: no h1; sticky area bar (61px) under sticky desktop nav; "Make this yours" sign-in banner; "7 results in Sacramento-Roseville, CA" then "7 results" again; grid 1 col@360, 3@768, 4@1024, 5@1280–1440, 7@1920 while the search bar caps at 1024px; List/Map toggle sits 1769px down @390 and 586px down @1440, not sticky; area pill 32px tall (<44)
A10: S009 | B10: /explore | C10: Explore (signed in) - Following row | D10: Public browse & detail | E10: state | F10: /explore | G10: browse/list+map | H10: signed in, follower, member | I10: Signed-in variant: no banner, adds horizontally-scrolling 'Announcements from Pages you follow' row above results; announcements returned in full | J10: Sticky search row > (no banner) > 'Announcements from Pages you follow' heading + horizontal snap carousel of cards (only when non-empty) > result count > grid w/ inline List/Map toggle after card 4 > rest of grid | K10: yes - carousel cards w-[min(78vw,20rem)] | L10: partial - carousel stays a single horizontal scroller at every width even when there is room for a grid; same unconstrained width as base page | M10: md: (FollowingRow md:-mx-6 md:px-6) | N10: • FollowingRow.tsx:45 horizontal scroller at all widths - on a 1440px screen a few 320px cards sit in a scroll strip with no scroll affordance/arrows • Following row heading is text-sm (FollowingRow.tsx:40) while there is no heading at all for the main results - hierarchy is inverted / main list has no visible title • Signed-in-with-no-follows sees no row and no hint that following is possible (FollowingRow.tsx:32 returns null) | O10: src/components/browse/BrowseSurface.tsx:183-193; src/components/browse/FollowingRow.tsx:33-58; src/app/explore/load.ts:85-87,186-205 | P10: Code
A11: S010 | B11: /explore | C11: Explore search expanded | D11: Public browse & detail | E11: state | F11: /explore | G11: browse/list+map | H11: signed out, signed in | I11: Tapping search icon expands a full-width input row under the sticky bar | J11: Sticky row: Area pill | Search (aria-expanded) | Filters > second sticky row: search input 'Search Pages and posts' with X (clears AND collapses) | K11: yes | L11: partial - input capped at max-w-5xl | M11: md: | N11: • Clear button (X) both clears the query and collapses the input (ExploreSearchBar.tsx:51-55,140-147) - no way to clear without losing the field • Search toggle icon remains visible when expanded so there are two controls that collapse search (icon and X) | O11: src/components/explore/ExploreSearchBar.tsx:43,88-150 | P11: Code
A12: S011 | B12: /explore | C12: Explore loading fallback | D12: Public browse & detail | E12: state | F12: /explore | G12: empty/error | H12: signed out, signed in | I12: Suspense fallback 'Loading…' while BrowseSurface (useSearchParams) suspends | J12: Plain 'Loading…' text, p-4 | K12: yes (bare text) | L12: no - unstyled text top-left | M12: none | N12: • No loading.tsx for /explore; page awaits loadBrowse() (page.tsx:26) BEFORE the Suspense boundary, so the server wait shows nothing and the fallback is effectively never seen; no skeleton | O12: src/app/explore/page.tsx:29 | P12: Code
A13: S012 | B13: /explore | C13: Explore map view | D13: Public browse & detail | E13: state | F13: /explore | G13: browse/list+map | H13: signed out, signed in | I13: Mapbox map of grouped pins for current results | J13: Sticky search row > banner/following row (still above) > result-count NOT shown > map h-[70vh] rounded > List/Map toggle BELOW the map | K13: yes - 70vh map, toggle below | L13: partial - map stretches full viewport width (no max-w); no side list; same single-column at all widths | M13: md: (md:px-6) | N13: • Toggle position flips: in list view it is mid-grid after card 4, in map view it is under the map (src/components/browse/BrowseSurface.tsx:256-258 vs 276) - control jumps location between views • View state is not in URL (src/components/browse/BrowseSurface.tsx:62-63) - back/refresh always returns to List • No list+map side-by-side on wide screens despite lots of horizontal room • Map view drops the result count, so the user loses '0 results' feedback when pins are empty | O13: src/components/browse/BrowseSurface.tsx:269-277; src/components/browse/BrowseMap.tsx:23-115 | P13: Code
A14: S013 | B14: /explore | C14: Map pin popup | D14: Public browse & detail | E14: state | F14: /explore | G14: browse/list+map | H14: signed out, signed in | I14: Card overlay on map listing up to 3 results at a pin | J14: Pin name > up to 3 lines (post body or description) > 'N more here' > 'Open Page' link | Close | K14: yes - absolute bottom-4 inset-x-4 | L14: partial - stretches full map width (left-4 right-4) with no max width | M14: none | N14: • Popup lists posts but only offers 'Open Page' - individual posts not linkable (BrowseMap.tsx:83-103) • Raw border-neutral-200 (BrowseMap.tsx:77) • Not a dialog, no Escape handling; pin markers are divs with click only (no keyboard access) BrowseMap.tsx:56-62 | O14: src/components/browse/BrowseMap.tsx:74-113 | P14: Code
A15: S014 | B15: /explore | C15: Metro not covered panel (signed out) | D15: Public browse & detail | E15: state | F15: /explore | G15: form/wizard | H15: signed out | I15: Explains SocialUs isn't in that metro, shows example cards, collects email for waitlist | J15: '← All areas' back link > H2 'SocialUs isn't running in {metro} yet' + explainer > ExampleBlock (dashed box, 4 fake cards) > 'Tell us you're here' box: role radios > email input > purpose note > 'Count me in' (btn-primary) > 'Or sign in, if you already have an account' > error | K15: yes - inside bottom sheet | L15: yes - inside sm+ centered max-w-md modal; ExampleBlock compact grid ~2 cols | M15: sm: (inherited from ScopeSheet) | N15: • Long form + 4-card example grid crammed in a max-h-[75vh] sheet (ScopeSheet.tsx:101) - the primary 'Count me in' is below the fold on phones • Example block comes BEFORE the action; order puts decoration between the question and the form | O15: src/components/explore/MetroNotCoveredPanel.tsx:161-259 (signed-out branch 193-235); src/components/cards/ExampleBlock.tsx | P15: Code + verified in prod | Q15: Verified 360–1920: no h1; sticky area bar (61px) under sticky desktop nav; "Make this yours" sign-in banner; "7 results in Sacramento-Roseville, CA" then "7 results" again; grid 1 col@360, 3@768, 4@1024, 5@1280–1440, 7@1920 while the search bar caps at 1024px; List/Map toggle sits 1769px down @390 and 586px down @1440, not sticky; area pill 32px tall (<44)
A16: S015 | B16: /explore | C16: Metro not covered panel (signed in) | D16: Public browse & detail | E16: state | F16: /explore | G16: form/wizard | H16: signed in | I16: Signed-in variant: role radios + 'Count me in' only (no email); joined confirmation | J16: '← All areas' > heading + explainer > ExampleBlock > 'Tell us you're here': role radios > 'Count me in' > (after) 'Done — you're counted in {metro}.' | K16: yes | L16: yes - in modal | M16: sm: | N16: • After joining, no CTA back to browsing - only the small '← All areas' link (MetroNotCoveredPanel.tsx:164-170) | O16: src/components/explore/MetroNotCoveredPanel.tsx:236-240,89-102 | P16: Code
A17: S016 | B17: /explore | C17: Filter sheet | D17: Public browse & detail | E17: sheet | F17: /explore | G17: browse/list+map | H17: signed out, signed in | I17: Schedule radio pills + tag checkboxes, committed on 'Show results' | J17: Header: X close | 'Filters' | 'Clear all' (when draft active, commits immediately) > Schedule group (pill radios) > Tags group (only if tags exist) > Footer: 'Show results' full-width | K17: yes - bottom sheet max-h-70vh, safe-area padding | L17: yes - md+ becomes floating panel right-4 top-28 w-96 | M17: md: | N17: • 'Clear all' commits and closes immediately (ExploreFilterSheet.tsx:144-147) while every other change is a draft - inconsistent commit model • Footer button says 'Show results' with no count • Sheet breakpoint is md: while ScopeSheet on same screen switches at sm: (ScopeSheet.tsx:97,101) - the two overlays change shape at different widths | O17: src/components/explore/ExploreFilterSheet.tsx:112-211 | P17: Code
A18: S017 | B18: /explore | C18: Scope sheet - Choose your area | D18: Public browse & detail | E18: sheet | F18: /explore | G18: browse/list+map | H18: signed out, signed in | I18: Pick which metro Explore shows; uncovered metros open MetroNotCoveredPanel | J18: Title 'Choose your area' > search input 'Search areas' > 'Where SocialUs is running' list (current marked 'Showing') > 'Not covered yet' heading + explainer > up to 40 not-yet rows 'Not yet →' > 'N more — search to narrow' | K18: yes - bottom sheet max-h-75vh scrolls | L18: yes - sm+ centered modal max-w-md | M18: sm: | N18: • No visible close button; only an invisible full-screen backdrop <button aria-label='Close'> (ScopeSheet.tsx:98) - no Escape key, no focus trap, no body scroll lock, unlike ExploreFilterSheet • Stale comment says not-covered rows are 'not tappable' (ScopeSheet.tsx:129-130) but they are buttons (81-93); explainer copy 'you can't browse them yet' sits above tappable rows • Raw text-neutral-500 headings (ScopeSheet.tsx:120,131) • Uses sm: breakpoint while sibling filter sheet uses md: | O18: src/components/explore/ScopeSheet.tsx:96-152 | P18: Code
A19: S018 | B19: /explore | C19: Metro standing dialog | D19: Public browse & detail | E19: modal | F19: /explore | G19: dashboard/manage | H19: signed out, signed in | I19: After waitlist join, shows count 'N of target' and message | J19: Title (metro name) > big count 'N of T' (if known) > message > 'Got it' button | K19: yes - fixed inset-x-4 centered | L19: yes - md: w-96 centered | M19: md: | N19: • Modal stacked on top of the ScopeSheet modal (z-50 over z-50) - two modals deep • Raw text-neutral-600 (MetroStandingDialog.tsx:76,80) • Escape handler only on dialog onKeyDown; no focus trap | O19: src/components/metro/MetroStandingDialog.tsx:50-92 | P19: Code
A20: S019 | B20: /explore | C20: Explore - no area resolvable | D20: Public browse & detail | E20: empty | F20: /explore | G20: empty/error | H20: signed out, signed in | I20: When no metro can be resolved, all controls are hidden and a card asks to choose an area | J20: Card: 'We don't know which area to show you yet.' > 'Choose your area' underline button (opens ScopeSheet) | K20: yes | L20: partial - mx-auto max-w-xl centered card | M20: md: (md:px-6 md:pb-24) | N20: • Search bar, filters and banner are removed entirely in this state, so the only header is the global nav; the area control moves from top pill to a body link - inconsistent location for the same control | O20: src/components/browse/BrowseSurface.tsx:140-166; src/app/explore/load.ts:79-81 | P20: Code
A21: S020 | B21: /explore | C21: Explore - no results | D21: Public browse & detail | E21: empty | F21: /explore | G21: empty/error | H21: signed out, signed in | I21: Search/filters/metro yield nothing | J21: Result count '0 results' > 'Nothing here yet — try another filter' > 'Clear filters' (underline) > 'Or look at another area' (muted underline, opens ScopeSheet) > List/Map toggle | K21: yes | L21: partial - text centered in unconstrained section | M21: md: | N21: • 'Clear filters' shown even when no filters/query are active (no hasBrowseFilters/query check at src/components/browse/BrowseSurface.tsx:228-234) - for an empty metro it is a no-op • Copy mismatch: empty says 'try another filter' but filters live behind an icon with no label | O21: src/components/browse/BrowseSurface.tsx:220-247,267 | P21: Code
A22: S021 | B22: /explore | C22: Explore - load error | D22: Public browse & detail | E22: error | F22: /explore | G22: empty/error | H22: signed out, signed in | I22: Feed RPC failed or metro switch action failed | J22: Sticky search row > result count '0 results' > 'We couldn't load {metro} just now. Try again in a moment.' > List/Map toggle | K22: yes | L22: partial - same unconstrained width | M22: md: | N22: • No retry button - message says 'Try again' but offers no control (src/components/browse/BrowseSurface.tsx:217-219); dead end other than reload • Result count '0 results' still renders above the error (src/components/browse/BrowseSurface.tsx:211-214), contradicting it • List/Map toggle still renders under the error (src/components/browse/BrowseSurface.tsx:267) | O22: src/components/browse/BrowseSurface.tsx:216-219; src/app/explore/load.ts:131-146; src/components/browse/BrowseSurface.tsx:85-92 | P22: Code
A23: S022 | B23: /following | C23: Following (legacy vendors list) | D23: Public browse & detail | E23: page | G23: feed | H23: signed in | I23: Lists vendors the user follows with next market date | J23: H1 'Following' > list rows: thumbnail (links /vendors/slug) | name, tagline, 'Next: market · date' | Follow/Following pill | K23: yes | L23: partial - max-w-3xl centered single column | M23: md: (md:px-6) | N23: • UNREACHABLE: next.config.ts:9 redirects /following -> /you/following before this page renders (verified in prod); file is dead code reading retired tables and linking to /vendors/* (no route) • Reads legacy 'follows'/'businesses'/'markets' tables (src/app/following/page.tsx:40-55) that HomeFeed.tsx:82-85 states do not exist - page is effectively always empty • Links to /vendors/{slug} (src/app/following/page.tsx:130,140) but there is no app/vendors route - 404 dead ends • Duplicates /you/following (src/app/you/following exists); BottomNav maps /following to the You tab (BottomNav.tsx:14) but nothing links here • Vendor/market vocabulary ('vendors', 'market') conflicts with Page/announcement vocabulary used on Explore • Raw neutral-*/amber-100 colours (src/app/following/page.tsx:128,131,151) | O23: src/app/following/page.tsx:25-163; src/components/FollowButton.tsx | P23: Code
A24: S023 | B24: /following | C24: Following - signed out | D24: Public browse & detail | E24: state | F24: /following | G24: auth | H24: signed out | I24: Gate asking to sign in | J24: H1 'Following' > 'Sign up to follow vendors…' > 'Sign in' button | K24: yes | L24: partial - max-w-md centered | M24: none | N24: • UNREACHABLE: next.config.ts:9 redirects /following -> /you/following before this page renders (verified in prod); file is dead code reading retired tables and linking to /vendors/* (no route) • Body says 'Sign up' but button says 'Sign in' (src/app/following/page.tsx:90,95) • Button uses rounded-md accent (not btn-primary) - inconsistent primary style (src/app/following/page.tsx:93) | O24: src/app/following/page.tsx:86-99 | P24: Code
A25: S024 | B25: /following | C25: Following - loading | D25: Public browse & detail | E25: state | F25: /following | G25: empty/error | H25: signed in | I25: Client fetch in progress | J25: H1 > 'Loading…' text | K25: yes | L25: partial | M25: md: | N25: • UNREACHABLE: next.config.ts:9 redirects /following -> /you/following before this page renders (verified in prod); file is dead code reading retired tables and linking to /vendors/* (no route) • Before auth resolves (authed===null) the signed-in shell renders, then may flip to the signed-out gate - layout flash (src/app/following/page.tsx:28,86) | O25: src/app/following/page.tsx:107 | P25: Code
A26: S025 | B26: /following | C26: Follow toast | D26: Public browse & detail | E26: state | F26: /following | G26: redirect/system | H26: signed in | I26: Transient 'Following X' / error toast | J26: Fixed pill bottom-20 centered | K26: yes | L26: yes | M26: none | N26: • Toast uses raw bg-zinc-800 (Toast.tsx:24) while ReportControl confirmation uses charcoal token - two toast styles | O26: src/components/FollowButton.tsx:103; src/components/Toast.tsx:24 | P26: Code
A27: S026 | B27: /following | C27: Auth gate modal (Follow) | D27: Public browse & detail | E27: modal | F27: /following | G27: auth | H27: signed out | I27: Sign-up prompt when a signed-out user taps Follow | J27: X close > H3 headline 'Sign up to follow {vendor}' > subtext > 'Sign in' btn-primary > 'We email you a link — no password' > divider > 'Are you a business owner? List your business →' (/join) | K27: yes - bottom aligned | L27: yes - md: centered max-w-sm | M27: md: | N27: • Effectively unreachable: its only caller FollowButton renders only inside signed-in /following rows (following/page.tsx:86-99 returns the gate first) • Headline says 'Sign up' but button says 'Sign in' (AuthGateModal.tsx:41,49) • No role=dialog/aria-modal (AuthGateModal.tsx:23-28) so NavVisibilityProvider does not treat it as an overlay • 'no password' contradicts /join step 1 'Email and password' (join/page.tsx:102) | O27: src/components/AuthGateModal.tsx:17-63; src/components/FollowButton.tsx:46-49,105-111 | P27: Code
A28: S027 | B28: /following | C28: Following - empty | D28: Public browse & detail | E28: empty | F28: /following | G28: empty/error | H28: signed in | I28: No follows | J28: H1 > 'You're not following anyone yet.' > 'Browse vendors' link -> /explore | K28: yes | L28: partial - max-w-3xl | M28: md: | N28: • UNREACHABLE: next.config.ts:9 redirects /following -> /you/following before this page renders (verified in prod); file is dead code reading retired tables and linking to /vendors/* (no route) • Empty <ul> still rendered beneath (src/app/following/page.tsx:118) | O28: src/app/following/page.tsx:109-116 | P28: Code
A29: S028 | B29: /g/[handle] | C29: Page (signed out) | D29: Public browse & detail | E29: page | G29: detail | H29: signed out | I29: Public Page for a business/group; signed-out gets withheld announcement summary | J29: Header row: H1 name | badge | ⋯ (Report -> sign-in link) > founder > placement > description > social links > 'Sign in to follow' (btn-primary) > Announcements: withheld card ('N announcements this week', details-for-members copy, 'Sign up to see what's happening' accent button) > 'Products & services' plain-text rows | K29: yes | L29: partial - max-w-3xl centered single column; no responsive prefixes in the page body | M29: none in page body (overlays use md:) | N29: • Two competing primaries for the same sign-in: 'Sign in to follow' btn-primary (src/components/group/ShopPublicPage.tsx:215, FollowPageButton.tsx:44) and 'Sign up to see what's happening' accent button (WithheldPagePosts.tsx:60) - different verbs, same /auth/login • The Page photo is never rendered: photoUrl is computed (src/components/group/ShopPublicPage.tsx:69-76) but only used for the owner hidden-photo notice - visitors see no image • Products & services rows are plain text, not links (src/components/group/ShopPublicPage.tsx:276-278) - dead ends; item detail pages unreachable from their Page • Report (⋯) sits in the title row before Follow (src/components/group/ShopPublicPage.tsx:117) - a moderation control is more prominent than the main action • Raw gray-* colours (src/components/group/ShopPublicPage.tsx:152,167,182,188,265,267) • Terminology: component/empty copy says 'Shop' ('This Shop', ShopPublicPage.tsx:269) while the product calls it a Page | O29: src/app/g/[handle]/page.tsx:39-65; src/components/group/ShopPublicPage.tsx:58-285; src/components/group/WithheldPagePosts.tsx:28-69; src/components/group/FollowPageButton.tsx:41-48 | P29: Code + verified in prod | Q29: Verified 390/1440/1920 (The Good Loaf, Folsom Lake Floaters): 768px column at every width (40% of 1920); "Sign in to follow"; Products & services are plain text (no item links in HTML)
A30: S029 | B30: /g/[handle] | C30: Page (signed in, not following) | D30: Public browse & detail | E30: state | F30: /g/[handle] | G30: detail | H30: signed in | I30: Signed-in visitor: Follow button; full announcements list (RLS decides which are visible) | J30: Header row: H1 Page name | local-owner badge | ⋯ overflow (ml-auto) > founder (avatar+name, links /m/ only if published) > placement label > description > social links > Follow button > Announcements > 'Products & services' list (Follow btn-primary) > Announcements list: body, when·where, Add to calendar, posted date (hidden entirely if none visible) | K30: yes | L30: partial - max-w-3xl | M30: none | N30: • Announcements section disappears entirely when empty for visitors (PagePosts.tsx:133) so section order shifts between Pages • Which follower-only posts a signed-in non-follower sees is decided by RLS - unclear from code whether a 'followers only' hint is shown (none found in PagePosts) • Raw text-gray-500 post date (PagePosts.tsx:409) | O30: src/components/group/ShopPublicPage.tsx:215-258; src/components/group/PagePosts.tsx:133,270-434 | P30: Code
A31: S030 | B31: /g/[handle] | C31: Page (follower) | D31: Public browse & detail | E31: state | F31: /g/[handle] | G31: detail | H31: follower | I31: Viewer follows: 'Following' outline button; toggles to unfollow on tap | J31: Header row: H1 Page name | local-owner badge | ⋯ overflow (ml-auto) > founder (avatar+name, links /m/ only if published) > placement label > description > social links > Follow button > Announcements > 'Products & services' list ('Following' outline button) > Announcements (incl. follower-audience posts per RLS) | K31: yes | L31: partial - max-w-3xl | M31: none | N31: • Tapping 'Following' unfollows immediately with no confirm (FollowPageButton.tsx:49-57) | O31: src/components/group/ShopPublicPage.tsx:215-223; src/components/group/FollowPageButton.tsx:65-79 | P31: Code
A32: S031 | B32: /g/[handle] | C32: Page (member, private Page) | D32: Public browse & detail | E32: state | F32: /g/[handle] | G32: detail | H32: member | I32: Private-discoverability Page: button reads Join/Joined | J32: Header row: H1 Page name | local-owner badge | ⋯ overflow (ml-auto) > founder (avatar+name, links /m/ only if published) > placement label > description > social links > Follow button > Announcements > 'Products & services' list ('Join' / 'Joined' button; signed-out 'Sign in to join') | K32: yes | L32: partial | M32: none | N32: • Same control is 'Follow' or 'Join' depending on discoverability (FollowPageButton.tsx:37-38) with no explanation of the difference | O32: src/components/group/FollowPageButton.tsx:37-38 | P32: Code
A33: S032 | B33: /g/[handle] | C33: Report sent confirmation | D33: Public browse & detail | E33: state | F33: /g/[handle] | G33: redirect/system | H33: signed in | I33: Fixed bottom toast after report | J33: Charcoal pill: thank-you text + 'Dismiss' | K33: yes - fixed bottom-20 above nav | L33: yes - md: centered w-96 | M33: md: | N33: • Does not auto-dismiss; differs from Toast.tsx style (zinc-800, auto-hide) | O33: src/components/group/ReportControl.tsx:83-101 | P33: Code
A34: S033 | B34: /g/[handle] | C34: g/[handle] owner view — see owner-page-spec.md | D34: Public browse & detail | E34: state | F34: /g/[handle] | G34: dashboard/manage | H34: owner | I34: Documented elsewhere | J34: see owner-page-spec.md | K34: see owner-page-spec.md | L34: see owner-page-spec.md | M34: see owner-page-spec.md | O34: src/components/group/ShopPublicPage.tsx | P34: Code
A35: S034 | B35: /g/[handle] | C35: Page overflow menu | D35: Public browse & detail | E35: drawer | F35: /g/[handle] | G35: detail | H35: signed out, signed in, follower, member | I35: ⋯ dropdown with single item 'Report to the operator' | J35: Menu (absolute right-0): 'Report to the operator' (signed out: link to sign-in) | K35: yes | L35: yes | M35: none | N35: • A menu with exactly one item - extra tap for a single action • 'operator' is internal vocabulary in a user-facing label (ReportControl.tsx:61) | O35: src/components/group/PageOverflowMenu.tsx:47-100; src/components/group/ReportControl.tsx:57-64 | P35: Code
A36: S035 | B36: /g/[handle] | C36: Report sheet | D36: Public browse & detail | E36: sheet | F36: /g/[handle] | G36: form/wizard | H36: signed in, follower, member | I36: Free-text report to a person | J36: Header: X | 'Report {Page}' > 'This goes to a person, not a queue.' > 'What's wrong?' textarea > error > footer 'Send' | K36: yes - bottom sheet | L36: yes - md: centered w-[28rem] top-24 | M36: md: | N36: • Close X on the left and title next to it - same pattern as filter sheet, but ScopeSheet has no X at all (inconsistent sheet chrome) | O36: src/components/group/ReportSheet.tsx:85-174 | P36: Code
A37: S036 | B37: /g/[handle] | C37: Page - nothing listed | D37: Public browse & detail | E37: empty | F37: /g/[handle] | G37: empty/error | H37: signed out, signed in, follower, member | I37: Page has no items | J37: 'Products & services' > dashed box 'Nothing listed yet' + '{founder} hasn't listed anything yet — check back soon.' | K37: yes | L37: partial | M37: none | N37: • Empty items section always shown to visitors while empty Announcements is hidden (PagePosts.tsx:133) - inconsistent empty-section policy • Raw gray-* (src/components/group/ShopPublicPage.tsx:265,267) | O37: src/components/group/ShopPublicPage.tsx:262-273 | P37: Code
A38: S037 | B38: /g/[handle] | C38: Page not found | D38: Public browse & detail | E38: error | F38: /g/[handle] | G38: empty/error | H38: signed out, signed in | I38: Unknown/draft (non-owner) handle -> notFound() | J38: Next default 404 | K38: partial | L38: partial | M38: none | N38: • Default Next 404 | O38: src/app/g/[handle]/page.tsx:43-44 | P38: Code + verified in prod | Q38: Verified /g/nope-123: default 404
A39: S038 | B39: /g/[handle] | C39: Page stale-handle redirect | D39: Public browse & detail | E39: redirect | G39: redirect/system | H39: signed out, signed in | I39: Non-canonical handle 308s to canonical /g/<slug>-<id> | J39: permanentRedirect(found.redirectTo) | K39: n/a | L39: n/a | M39: none | O39: src/app/g/[handle]/page.tsx:43-45 | P39: Code
A40: S039 | B40: /join | C40: Join - vendor pitch (signed out) | D40: Public browse & detail | E40: page | G40: form/wizard | H40: signed out | I40: Marketing page recruiting farmers-market vendors | J40: Hero: eyebrow 'For vendors' > H1 'Sell at a farmers market? Get listed.' > lede > CTAs: 'Sign up as a vendor →' (primary) + 'Already a member? Log in' (secondary) > Why: 3 benefit cards > How it works: 4 numbered steps > 'Start my listing →' > Share with another vendor: URL + 'Copy link' | K40: yes - stacked, CTAs column | L40: partial - max-w-3xl centered; benefits md:grid-cols-3; CTAs sm:flex-row; no side-by-side layout beyond that | M40: sm:, md: | N40: • Both hero CTAs go to the identical URL for signed-out users (src/app/join/page.tsx:40,64,71) - 'Sign up' and 'Log in' are the same action • Three differently-worded primaries for one action on one page: 'Sign up as a vendor →', 'Start my listing →', (signed-in) 'List my booth →' (src/app/join/page.tsx:67,125) • Step 1 claims 'Email and password' (src/app/join/page.tsx:102) while AuthGateModal says no password / magic link • Vendor/farmers-market framing and claims 'in the feed, the map, searchable by product' (src/app/join/page.tsx:53-56,111) describe the retired vendor model, not Pages • Not reachable from main nav; only linked from orphaned RecruitmentGrid and unreachable AuthGateModal • Raw neutral-* everywhere (src/app/join/page.tsx:54,57,72,81,...) | O40: src/app/join/page.tsx:24-156 | P40: Code + verified in prod | Q40: Verified 390/1440: column 768px at all widths (53% of 1440); "Sign up as a vendor" and "Already a member? Log in" both go to /auth/login; copy says "vendor"
...

Sheet Counts
A1: Screen type | B1: All rows | C1: Pages | D1: Overlays (modal/sheet/drawer) | E1: Wizard steps | F1: States | G1: Empty + error | H1: Verified in prod
A2: browse/list+map | B2: =COUNTIF(Screens!$G$2:$G$153,A2) -> 9 | C2: =COUNTIFS(Screens!$G$2:$G$153,A2,Screens!$E$2:$E$153,"page") -> 1 | D2: =COUNTIFS(Screens!$G$2:$G$153,A2,Screens!$E$2:$E$153,"modal")+COUNTIFS(Screens!$G$2:$G$153,A2,Screens!$E$2:$E$153,"sheet")+COUNTIFS(Screens!$G$2:$G$153,A2,Screens!$E$2:$E$153,"drawer") -> 2 | E2: =COUNTIFS(Screens!$G$2:$G$153,A2,Screens!$E$2:$E$153,"step") -> 0 | F2: =COUNTIFS(Screens!$G$2:$G$153,A2,Screens!$E$2:$E$153,"state") -> 6 | G2: =COUNTIFS(Screens!$G$2:$G$153,A2,Screens!$E$2:$E$153,"empty")+COUNTIFS(Screens!$G$2:$G$153,A2,Screens!$E$2:$E$153,"error") -> 0 | H2: =COUNTIFS(Screens!$G$2:$G$153,A2,Screens!$P$2:$P$153,"Code + verified in prod") -> 1
A3: detail | B3: =COUNTIF(Screens!$G$2:$G$153,A3) -> 16 | C3: =COUNTIFS(Screens!$G$2:$G$153,A3,Screens!$E$2:$E$153,"page") -> 9 | D3: =COUNTIFS(Screens!$G$2:$G$153,A3,Screens!$E$2:$E$153,"modal")+COUNTIFS(Screens!$G$2:$G$153,A3,Screens!$E$2:$E$153,"sheet")+COUNTIFS(Screens!$G$2:$G$153,A3,Screens!$E$2:$E$153,"drawer") -> 1 | E3: =COUNTIFS(Screens!$G$2:$G$153,A3,Screens!$E$2:$E$153,"step") -> 0 | F3: =COUNTIFS(Screens!$G$2:$G$153,A3,Screens!$E$2:$E$153,"state") -> 6 | G3: =COUNTIFS(Screens!$G$2:$G$153,A3,Screens!$E$2:$E$153,"empty")+COUNTIFS(Screens!$G$2:$G$153,A3,Screens!$E$2:$E$153,"error") -> 0 | H3: =COUNTIFS(Screens!$G$2:$G$153,A3,Screens!$P$2:$P$153,"Code + verified in prod") -> 1
A4: feed | B4: =COUNTIF(Screens!$G$2:$G$153,A4) -> 4 | C4: =COUNTIFS(Screens!$G$2:$G$153,A4,Screens!$E$2:$E$153,"page") -> 3 | D4: =COUNTIFS(Screens!$G$2:$G$153,A4,Screens!$E$2:$E$153,"modal")+COUNTIFS(Screens!$G$2:$G$153,A4,Screens!$E$2:$E$153,"sheet")+COUNTIFS(Screens!$G$2:$G$153,A4,Screens!$E$2:$E$153,"drawer") -> 0 | E4: =COUNTIFS(Screens!$G$2:$G$153,A4,Screens!$E$2:$E$153,"step") -> 0 | F4: =COUNTIFS(Screens!$G$2:$G$153,A4,Screens!$E$2:$E$153,"state") -> 1 | G4: =COUNTIFS(Screens!$G$2:$G$153,A4,Screens!$E$2:$E$153,"empty")+COUNTIFS(Screens!$G$2:$G$153,A4,Screens!$E$2:$E$153,"error") -> 0 | H4: =COUNTIFS(Screens!$G$2:$G$153,A4,Screens!$P$2:$P$153,"Code + verified in prod") -> 0
A5: form/wizard | B5: =COUNTIF(Screens!$G$2:$G$153,A5) -> 37 | C5: =COUNTIFS(Screens!$G$2:$G$153,A5,Screens!$E$2:$E$153,"page") -> 2 | D5: =COUNTIFS(Screens!$G$2:$G$153,A5,Screens!$E$2:$E$153,"modal")+COUNTIFS(Screens!$G$2:$G$153,A5,Screens!$E$2:$E$153,"sheet")+COUNTIFS(Screens!$G$2:$G$153,A5,Screens!$E$2:$E$153,"drawer") -> 8 | E5: =COUNTIFS(Screens!$G$2:$G$153,A5,Screens!$E$2:$E$153,"step") -> 20 | F5: =COUNTIFS(Screens!$G$2:$G$153,A5,Screens!$E$2:$E$153,"state") -> 6 | G5: =COUNTIFS(Screens!$G$2:$G$153,A5,Screens!$E$2:$E$153,"empty")+COUNTIFS(Screens!$G$2:$G$153,A5,Screens!$E$2:$E$153,"error") -> 1 | H5: =COUNTIFS(Screens!$G$2:$G$153,A5,Screens!$P$2:$P$153,"Code + verified in prod") -> 2
A6: dashboard/manage | B6: =COUNTIF(Screens!$G$2:$G$153,A6) -> 9 | C6: =COUNTIFS(Screens!$G$2:$G$153,A6,Screens!$E$2:$E$153,"page") -> 4 | D6: =COUNTIFS(Screens!$G$2:$G$153,A6,Screens!$E$2:$E$153,"modal")+COUNTIFS(Screens!$G$2:$G$153,A6,Screens!$E$2:$E$153,"sheet")+COUNTIFS(Screens!$G$2:$G$153,A6,Screens!$E$2:$E$153,"drawer") -> 1 | E6: =COUNTIFS(Screens!$G$2:$G$153,A6,Screens!$E$2:$E$153,"step") -> 0 | F6: =COUNTIFS(Screens!$G$2:$G$153,A6,Screens!$E$2:$E$153,"state") -> 4 | G6: =COUNTIFS(Screens!$G$2:$G$153,A6,Screens!$E$2:$E$153,"empty")+COUNTIFS(Screens!$G$2:$G$153,A6,Screens!$E$2:$E$153,"error") -> 0 | H6: =COUNTIFS(Screens!$G$2:$G$153,A6,Screens!$P$2:$P$153,"Code + verified in prod") -> 3
A7: settings | B7: =COUNTIF(Screens!$G$2:$G$153,A7) -> 3 | C7: =COUNTIFS(Screens!$G$2:$G$153,A7,Screens!$E$2:$E$153,"page") -> 1 | D7: =COUNTIFS(Screens!$G$2:$G$153,A7,Screens!$E$2:$E$153,"modal")+COUNTIFS(Screens!$G$2:$G$153,A7,Screens!$E$2:$E$153,"sheet")+COUNTIFS(Screens!$G$2:$G$153,A7,Screens!$E$2:$E$153,"drawer") -> 0 | E7: =COUNTIFS(Screens!$G$2:$G$153,A7,Screens!$E$2:$E$153,"step") -> 0 | F7: =COUNTIFS(Screens!$G$2:$G$153,A7,Screens!$E$2:$E$153,"state") -> 1 | G7: =COUNTIFS(Screens!$G$2:$G$153,A7,Screens!$E$2:$E$153,"empty")+COUNTIFS(Screens!$G$2:$G$153,A7,Screens!$E$2:$E$153,"error") -> 0 | H7: =COUNTIFS(Screens!$G$2:$G$153,A7,Screens!$P$2:$P$153,"Code + verified in prod") -> 0
A8: auth | B8: =COUNTIF(Screens!$G$2:$G$153,A8) -> 13 | C8: =COUNTIFS(Screens!$G$2:$G$153,A8,Screens!$E$2:$E$153,"page") -> 2 | D8: =COUNTIFS(Screens!$G$2:$G$153,A8,Screens!$E$2:$E$153,"modal")+COUNTIFS(Screens!$G$2:$G$153,A8,Screens!$E$2:$E$153,"sheet")+COUNTIFS(Screens!$G$2:$G$153,A8,Screens!$E$2:$E$153,"drawer") -> 3 | E8: =COUNTIFS(Screens!$G$2:$G$153,A8,Screens!$E$2:$E$153,"step") -> 2 | F8: =COUNTIFS(Screens!$G$2:$G$153,A8,Screens!$E$2:$E$153,"state") -> 5 | G8: =COUNTIFS(Screens!$G$2:$G$153,A8,Screens!$E$2:$E$153,"empty")+COUNTIFS(Screens!$G$2:$G$153,A8,Screens!$E$2:$E$153,"error") -> 1 | H8: =COUNTIFS(Screens!$G$2:$G$153,A8,Screens!$P$2:$P$153,"Code + verified in prod") -> 3
A9: empty/error | B9: =COUNTIF(Screens!$G$2:$G$153,A9) -> 35 | C9: =COUNTIFS(Screens!$G$2:$G$153,A9,Screens!$E$2:$E$153,"page") -> 0 | D9: =COUNTIFS(Screens!$G$2:$G$153,A9,Screens!$E$2:$E$153,"modal")+COUNTIFS(Screens!$G$2:$G$153,A9,Screens!$E$2:$E$153,"sheet")+COUNTIFS(Screens!$G$2:$G$153,A9,Screens!$E$2:$E$153,"drawer") -> 0 | E9: =COUNTIFS(Screens!$G$2:$G$153,A9,Screens!$E$2:$E$153,"step") -> 0 | F9: =COUNTIFS(Screens!$G$2:$G$153,A9,Screens!$E$2:$E$153,"state") -> 8 | G9: =COUNTIFS(Screens!$G$2:$G$153,A9,Screens!$E$2:$E$153,"empty")+COUNTIFS(Screens!$G$2:$G$153,A9,Screens!$E$2:$E$153,"error") -> 27 | H9: =COUNTIFS(Screens!$G$2:$G$153,A9,Screens!$P$2:$P$153,"Code + verified in prod") -> 4
A10: redirect/system | B10: =COUNTIF(Screens!$G$2:$G$153,A10) -> 21 | C10: =COUNTIFS(Screens!$G$2:$G$153,A10,Screens!$E$2:$E$153,"page") -> 0 | D10: =COUNTIFS(Screens!$G$2:$G$153,A10,Screens!$E$2:$E$153,"modal")+COUNTIFS(Screens!$G$2:$G$153,A10,Screens!$E$2:$E$153,"sheet")+COUNTIFS(Screens!$G$2:$G$153,A10,Screens!$E$2:$E$153,"drawer") -> 0 | E10: =COUNTIFS(Screens!$G$2:$G$153,A10,Screens!$E$2:$E$153,"step") -> 0 | F10: =COUNTIFS(Screens!$G$2:$G$153,A10,Screens!$E$2:$E$153,"state") -> 3 | G10: =COUNTIFS(Screens!$G$2:$G$153,A10,Screens!$E$2:$E$153,"empty")+COUNTIFS(Screens!$G$2:$G$153,A10,Screens!$E$2:$E$153,"error") -> 0 | H10: =COUNTIFS(Screens!$G$2:$G$153,A10,Screens!$P$2:$P$153,"Code + verified in prod") -> 6
A11: dev | B11: =COUNTIF(Screens!$G$2:$G$153,A11) -> 5 | C11: =COUNTIFS(Screens!$G$2:$G$153,A11,Screens!$E$2:$E$153,"page") -> 4 | D11: =COUNTIFS(Screens!$G$2:$G$153,A11,Screens!$E$2:$E$153,"modal")+COUNTIFS(Screens!$G$2:$G$153,A11,Screens!$E$2:$E$153,"sheet")+COUNTIFS(Screens!$G$2:$G$153,A11,Screens!$E$2:$E$153,"drawer") -> 0 | E11: =COUNTIFS(Screens!$G$2:$G$153,A11,Screens!$E$2:$E$153,"step") -> 0 | F11: =COUNTIFS(Screens!$G$2:$G$153,A11,Screens!$E$2:$E$153,"state") -> 0 | G11: =COUNTIFS(Screens!$G$2:$G$153,A11,Screens!$E$2:$E$153,"empty")+COUNTIFS(Screens!$G$2:$G$153,A11,Screens!$E$2:$E$153,"error") -> 0 | H11: =COUNTIFS(Screens!$G$2:$G$153,A11,Screens!$P$2:$P$153,"Code + verified in prod") -> 3
A12: Total | B12: =SUM(B2:B11) -> 152 | C12: =SUM(C2:C11) -> 26 | D12: =SUM(D2:D11) -> 15 | E12: =SUM(E2:E11) -> 22 | F12: =SUM(F2:F11) -> 40 | G12: =SUM(G2:G11) -> 29 | H12: =SUM(H2:H11) -> 23
A14: Kind | B14: Rows
A15: page | B15: =COUNTIF(Screens!$E$2:$E$153,"page") -> 26
A16: settings | B16: =COUNTIF(Screens!$E$2:$E$153,"settings") -> 1
A17: state | B17: =COUNTIF(Screens!$E$2:$E$153,"state") -> 40
A18: step | B18: =COUNTIF(Screens!$E$2:$E$153,"step") -> 22
A19: modal | B19: =COUNTIF(Screens!$E$2:$E$153,"modal") -> 5
A20: sheet | B20: =COUNTIF(Screens!$E$2:$E$153,"sheet") -> 6
A21: drawer | B21: =COUNTIF(Screens!$E$2:$E$153,"drawer") -> 4
A22: empty | B22: =COUNTIF(Screens!$E$2:$E$153,"empty") -> 13
A23: error | B23: =COUNTIF(Screens!$E$2:$E$153,"error") -> 16
A24: redirect | B24: =COUNTIF(Screens!$E$2:$E$153,"redirect") -> 15
A25: api | B25: =COUNTIF(Screens!$E$2:$E$153,"api") -> 4

Sheet Screen sizes
A1: Primary screen | B1: Route | C1: Content max width (px) | D1: How it lays out above phone | E1: 6" phone: % of width used | F1: 8" tablet: % of width used | G1: 11" tablet: % of width used | H1: 13" laptop: % of width used | I1: 15" laptop: % of width used | J1: 16" laptop: % of width used | K1: 27" monitor: % of width used | L1: Source
B2: Viewport width (px) → | E2: 390 | F2: 768 | G2: 1024 | H2: 1280 | I2: 1440 | J2: 1728 | K2: 2560
A3: Explore list: search/area bar | B3: /explore | C3: 1024 | D3: Capped at 1024px. The result grid below is NOT capped (auto-fill): 1 col@360, 3@768, 4@1024, 5@1280–1440, 7@1920, so grid and header edges stop lining up above ~1056px. List and map never side by side. | E3: =MIN(E$2-32,$C3)/E$2 -> 0.91794872 | F3: =MIN(F$2-32,$C3)/F$2 -> 0.95833333 | G3: =MIN(G$2-32,$C3)/G$2 -> 0.96875 | H3: =MIN(H$2-32,$C3)/H$2 -> 0.8 | I3: =MIN(I$2-32,$C3)/I$2 -> 0.71111111 | J3: =MIN(J$2-32,$C3)/J$2 -> 0.59259259 | K3: =MIN(K$2-32,$C3)/K$2 -> 0.4 | L3: Prod measured
A4: Explore list: result grid | B4: /explore | C4: none | D4: Full width; columns keep multiplying (7 at 1920) | E4: =(E$2-32)/E$2 -> 0.91794872 | F4: =(F$2-32)/F$2 -> 0.95833333 | G4: =(G$2-32)/G$2 -> 0.96875 | H4: =(H$2-32)/H$2 -> 0.975 | I4: =(I$2-32)/I$2 -> 0.97777778 | J4: =(J$2-32)/J$2 -> 0.98148148 | K4: =(K$2-32)/K$2 -> 0.9875 | L4: Prod measured
A5: Explore map view | B5: /explore?view=map | C5: none | D5: Map full width; no list beside it | E5: =(E$2-32)/E$2 -> 0.91794872 | F5: =(F$2-32)/F$2 -> 0.95833333 | G5: =(G$2-32)/G$2 -> 0.96875 | H5: =(H$2-32)/H$2 -> 0.975 | I5: =(I$2-32)/I$2 -> 0.97777778 | J5: =(J$2-32)/J$2 -> 0.98148148 | K5: =(K$2-32)/K$2 -> 0.9875 | L5: Code
A6: Page (visitor) | B6: /g/[handle] | C6: 768 | D6: Single 768px column at every width; no responsive prefixes | E6: =MIN(E$2-32,$C6)/E$2 -> 0.91794872 | F6: =MIN(F$2-32,$C6)/F$2 -> 0.95833333 | G6: =MIN(G$2-32,$C6)/G$2 -> 0.75 | H6: =MIN(H$2-32,$C6)/H$2 -> 0.6 | I6: =MIN(I$2-32,$C6)/I$2 -> 0.53333333 | J6: =MIN(J$2-32,$C6)/J$2 -> 0.44444444 | K6: =MIN(K$2-32,$C6)/K$2 -> 0.3 | L6: Prod measured
A7: Member profile | B7: /m/[handle] | C7: 768 | D7: Single column | E7: =MIN(E$2-32,$C7)/E$2 -> 0.91794872 | F7: =MIN(F$2-32,$C7)/F$2 -> 0.95833333 | G7: =MIN(G$2-32,$C7)/G$2 -> 0.75 | H7: =MIN(H$2-32,$C7)/H$2 -> 0.6 | I7: =MIN(I$2-32,$C7)/I$2 -> 0.53333333 | J7: =MIN(J$2-32,$C7)/J$2 -> 0.44444444 | K7: =MIN(K$2-32,$C7)/K$2 -> 0.3 | L7: Code
A8: Item detail (product / service / event) | B8: /m/../{p,s,e}, /p/../g/.. | C8: 672 | D8: Single column, no media or side column | E8: =MIN(E$2-32,$C8)/E$2 -> 0.91794872 | F8: =MIN(F$2-32,$C8)/F$2 -> 0.875 | G8: =MIN(G$2-32,$C8)/G$2 -> 0.65625 | H8: =MIN(H$2-32,$C8)/H$2 -> 0.525 | I8: =MIN(I$2-32,$C8)/I$2 -> 0.46666667 | J8: =MIN(J$2-32,$C8)/J$2 -> 0.38888889 | K8: =MIN(K$2-32,$C8)/K$2 -> 0.2625 | L8: Code
A9: Venue | B9: /p/[...place]/l/[slug] | C9: 768 | D9: Column; item grid 3 cols at md+ | E9: =MIN(E$2-32,$C9)/E$2 -> 0.91794872 | F9: =MIN(F$2-32,$C9)/F$2 -> 0.95833333 | G9: =MIN(G$2-32,$C9)/G$2 -> 0.75 | H9: =MIN(H$2-32,$C9)/H$2 -> 0.6 | I9: =MIN(I$2-32,$C9)/I$2 -> 0.53333333 | J9: =MIN(J$2-32,$C9)/J$2 -> 0.44444444 | K9: =MIN(K$2-32,$C9)/K$2 -> 0.3 | L9: Code
A10: Place landing (placeholder) | B10: /p/[...place] | C10: 896 | D10: Placeholder text | E10: =MIN(E$2-32,$C10)/E$2 -> 0.91794872 | F10: =MIN(F$2-32,$C10)/F$2 -> 0.95833333 | G10: =MIN(G$2-32,$C10)/G$2 -> 0.875 | H10: =MIN(H$2-32,$C10)/H$2 -> 0.7 | I10: =MIN(I$2-32,$C10)/I$2 -> 0.62222222 | J10: =MIN(J$2-32,$C10)/J$2 -> 0.51851852 | K10: =MIN(K$2-32,$C10)/K$2 -> 0.35 | L10: Code
A11: Join (vendor pitch) | B11: /join | C11: 768 | D11: Column; benefits 3 cols at md+ | E11: =MIN(E$2-32,$C11)/E$2 -> 0.91794872 | F11: =MIN(F$2-32,$C11)/F$2 -> 0.95833333 | G11: =MIN(G$2-32,$C11)/G$2 -> 0.75 | H11: =MIN(H$2-32,$C11)/H$2 -> 0.6 | I11: =MIN(I$2-32,$C11)/I$2 -> 0.53333333 | J11: =MIN(J$2-32,$C11)/J$2 -> 0.44444444 | K11: =MIN(K$2-32,$C11)/K$2 -> 0.3 | L11: Prod measured
A12: Sign in / password | B12: /auth/* | C12: 384 | D12: Fixed 384px column | E12: =MIN(E$2-32,$C12)/E$2 -> 0.91794872 | F12: =MIN(F$2-32,$C12)/F$2 -> 0.5 | G12: =MIN(G$2-32,$C12)/G$2 -> 0.375 | H12: =MIN(H$2-32,$C12)/H$2 -> 0.3 | I12: =MIN(I$2-32,$C12)/I$2 -> 0.26666667 | J12: =MIN(J$2-32,$C12)/J$2 -> 0.22222222 | K12: =MIN(K$2-32,$C12)/K$2 -> 0.15 | L12: Prod measured
A13: Onboarding | B13: /onboarding | C13: 448 | D13: Fixed 448px column | E13: =MIN(E$2-32,$C13)/E$2 -> 0.91794872 | F13: =MIN(F$2-32,$C13)/F$2 -> 0.58333333 | G13: =MIN(G$2-32,$C13)/G$2 -> 0.4375 | H13: =MIN(H$2-32,$C13)/H$2 -> 0.35 | I13: =MIN(I$2-32,$C13)/I$2 -> 0.31111111 | J13: =MIN(J$2-32,$C13)/J$2 -> 0.25925926 | K13: =MIN(K$2-32,$C13)/K$2 -> 0.175 | L13: Code
A14: You (signed out) | B14: /you | C14: 448 | D14: Fixed 448px column | E14: =MIN(E$2-32,$C14)/E$2 -> 0.91794872 | F14: =MIN(F$2-32,$C14)/F$2 -> 0.58333333 | G14: =MIN(G$2-32,$C14)/G$2 -> 0.4375 | H14: =MIN(H$2-32,$C14)/H$2 -> 0.35 | I14: =MIN(I$2-32,$C14)/I$2 -> 0.31111111 | J14: =MIN(J$2-32,$C14)/J$2 -> 0.25925926 | K14: =MIN(K$2-32,$C14)/K$2 -> 0.175 | L14: Prod measured
A15: You (signed in) | B15: /you | C15: 768 | D15: Column; Your Pages as auto-fill tiles | E15: =MIN(E$2-32,$C15)/E$2 -> 0.91794872 | F15: =MIN(F$2-32,$C15)/F$2 -> 0.95833333 | G15: =MIN(G$2-32,$C15)/G$2 -> 0.75 | H15: =MIN(H$2-32,$C15)/H$2 -> 0.6 | I15: =MIN(I$2-32,$C15)/I$2 -> 0.53333333 | J15: =MIN(J$2-32,$C15)/J$2 -> 0.44444444 | K15: =MIN(K$2-32,$C15)/K$2 -> 0.3 | L15: Code
A16: Your shops | B16: /you/sell | C16: 768 | D16: Column; 3 buttons per row do not wrap (crush name at 375) | E16: =MIN(E$2-32,$C16)/E$2 -> 0.91794872 | F16: =MIN(F$2-32,$C16)/F$2 -> 0.95833333 | G16: =MIN(G$2-32,$C16)/G$2 -> 0.75 | H16: =MIN(H$2-32,$C16)/H$2 -> 0.6 | I16: =MIN(I$2-32,$C16)/I$2 -> 0.53333333 | J16: =MIN(J$2-32,$C16)/J$2 -> 0.44444444 | K16: =MIN(K$2-32,$C16)/K$2 -> 0.3 | L16: Code
A17: Following (manage) | B17: /you/following | C17: 672 | D17: Column | E17: =MIN(E$2-32,$C17)/E$2 -> 0.91794872 | F17: =MIN(F$2-32,$C17)/F$2 -> 0.875 | G17: =MIN(G$2-32,$C17)/G$2 -> 0.65625 | H17: =MIN(H$2-32,$C17)/H$2 -> 0.525 | I17: =MIN(I$2-32,$C17)/I$2 -> 0.46666667 | J17: =MIN(J$2-32,$C17)/J$2 -> 0.38888889 | K17: =MIN(K$2-32,$C17)/K$2 -> 0.2625 | L17: Code
... A22: Area (scope) sheet | B22: sheet on /explore | C22: 448 | D22: Bottom sheet on phone; centred 448px modal at sm+ | E22: =MIN(E$2-32,$C22)/E$2 -> 0.91794872 | F22: =MIN(F$2-32,$C22)/F$2 -> 0.58333333 | G22: =MIN(G$2-32,$C22)/G$2 -> 0.4375 | H22: =MIN(H$2-32,$C22)/H$2 -> 0.35 | I22: =MIN(I$2-32,$C22)/I$2 -> 0.31111111 | J22: =MIN(J$2-32,$C22)/J$2 -> 0.25925926 | K22: =MIN(K$2-32,$C22)/K$2 -> 0.175 | L22: Code
A24: Reading it: under ~60% at 15–16" means most of the screen is empty margin. Max widths from code (max-w-*); prod measurement confirms Explore, Page, Join, auth and You (signed out). Assumes 16px side padding.

Sheet Top problems
A1: Problem | B1: Detail and evidence | C1: Where | D1: Source
A2: No wide layout anywhere | B2: lg:/xl:/2xl: are used 0 times; 105 of 126 .tsx files have no responsive prefix; content pages are single columns of 384–768px, so at 15–16" a Page uses ~53% of the width and at 27" ~30%. | C2: All content pages | D2: Code + prod measured
A3: Explore: List/Map toggle scrolls away and moves | B3: Toggle is inline after result card 4, not sticky (prod: 1769px down at 390, 586px down at 1440); in map view it sits under the map (BrowseSurface.tsx:50,256,276). | C3: /explore | D3: Code + prod measured
A4: Explore: header and grid on different widths | B4: Search/area bar capped at 1024px but the grid is uncapped: 5 columns at 1440, 7 at 1920; list and map never side by side; "7 results in Sacramento…" then "7 results" again; no h1. | C4: /explore | D4: Prod measured
A5: Create goes in a circle | B5: Nav Create → /you/sell, which sends anyone without an active Page back to /you; the empty state there says "Tap Create"; the entry that works is labelled "Sell". Same flow called Create / Sell / Page / shop. | C5: /you, /you/sell, nav | D5: Code
A6: Nav differs by size and never hides | B6: Phone order Explore · Create · You; desktop order Explore · You · Create + Sign in. Nav shows on auth, onboarding, admin and inside wizards; desktop nav links are 20px tall. | C6: Global | D6: Prod measured
A7: Sign-in asked for in many words | B7: "Sign in", "Sign in to follow", "Sign up to see what's happening", "Sign up as a vendor", "Already a member? Log in" — all go to /auth/login; /auth/signup redirects there; 3 sign-in surfaces (AuthGateModal, unused SignInPrompt, page). /auth/login doesn't forward signed-in users. | C7: /explore, /g, /join, /you | D7: Code + prod
A8: /you is three overlapping views | B8: Following summary strip plus a Following tab that always says "Nothing followed yet"; Saved tab always empty; Settings and Sign out hidden in a third tab, Sign out also in the badge; profile link → /onboarding which bounces to /. | C8: /you | D8: Code
A9: No shared page shell | B9: No not-found/error/loading files (default Next 404 in prod); every page title is just "SocialUs" (prod); h1 in 5 sizes, no page header component; 12 different max-widths. | C9: Global | D9: Code + prod
A10: Create and edit a Page don't match | B10: Name/Brand/Title, About/Description, Anchor Location/Address; links as URLs when creating, handles when editing; tags not editable and dropped on resume; Save scrolls away while "Done" sits beside it with equal weight and drops changes. | C10: Sell walkthrough, /g/[handle]/edit | D10: Code
A11: Dead ends and leftovers visible | B11: Products on a Page are plain text (no link to item pages, prod); /p/[place] shows placeholder text publicly; "Where is this made?" step has no input; /you signed out says "follow vendors" (prod); /following page is shadowed by a redirect and links to /vendors/*. | C11: Several | D11: Code + prod
A12: (Owner Page) | B12: Owner sees Follow + Report on own Page; tools in four places — see owner-page-spec.md. | C12: /g/[handle] owner | D12: Prior review

Sheet Shared UI
A1: Group | B1: Piece | C1: File | D1: Used by (files) | E1: Variants | F1: Token use | G1: Notes
A2: badges | B2: ExampleCard label badge | C2: components/cards/ExampleCard.tsx:57 | D2: 1 | F2: bg-fg/80 text-[11px]
A3: badges | B3: Filter active dot | C3: components/explore/ExploreSearchBar.tsx:112 | D3: 1 | F3: accent
A4: badges | B4: OwnershipBadge | C4: components/OwnershipBadge.tsx | D4: 0 | F4: lib/map-config hex | G4: ORPHAN; ignores ownership tokens.
A5: badges | B5: RecruitmentGrid badges | C5: components/RecruitmentGrid.tsx:100,123 | D5: 1 | F5: amber + text-[10px] | G5: Orphan.
A6: badges | B6: Sparkline | C6: components/Sparkline.tsx | D6: 0 | G6: ORPHAN.
A7: badges | B7: StatusDot | C7: components/cards/StatusDot.tsx | D7: 1 | F7: hex prop
A8: banners/notices/toasts | B8: Error text | C8: many | D8: 21 | E8: text-red-600 / red-500 / red-700 / var(--color-danger,#b00) | F8: raw palette + undefined var | G8: No danger token.
A9: banners/notices/toasts | B9: HiddenPhotoNotice | C9: components/group/HiddenPhotoNotice.tsx | D9: 1 | F9: tokens
A10: banners/notices/toasts | B10: Inline toasts (x5) | C10: components/sell/SellCta.tsx:195; components/sell/Add*Button.tsx:71/76; components/group/ReportControl.tsx:87 | D10: 5 | E10: neutral-900 / charcoal-700; bottom-4 / bottom-20 | F10: rolls own | G10: Toast re-implemented 5x.
A11: banners/notices/toasts | B11: LocallyOwnedClaim | C11: components/group/LocallyOwnedClaim.tsx | D11: 1 | F11: btn recipes
A12: banners/notices/toasts | B12: MakeThisYoursBanner | C12: components/feed/MakeThisYoursBanner.tsx | D12: 2 | F12: .card + btn-primary
A13: banners/notices/toasts | B13: PostingSafetyNote | C13: components/PostingSafetyNote.tsx | D13: 6 | F13: fg-muted
A14: banners/notices/toasts | B14: Toast | C14: components/Toast.tsx | D14: 1 | F14: bg-zinc-800, bottom-20 | G14: Only legacy FollowButton.
A15: buttons | B15: .btn-primary (recipe) | C15: app/globals.css | D15: 22 | E15: single; accent fill, rounded-xl(0.75rem), px-5 py-3 text-sm medium | F15: recipe | G15: 29 uses/22 files. ~21 other accent buttons roll their own.
A16: buttons | B16: .btn-secondary (recipe) | C16: app/globals.css | D16: 16 | E16: single; white + border | F16: recipe | G16: 20 uses/16 files.
A17: buttons | B17: Ad-hoc accent pill CTA | C17: app/join/page.tsx:65,123; components/auth/EmailFirstSignup.tsx:229,275; components/auth/MagicLinkForm.tsx:90; app/you/page.tsx:270; components/follows/FollowingManager.tsx:175; components/AuthCtaButtons.tsx:97,116; components/HomeFeed.tsx:179 | D17: 7 | E17: rounded-full px-4..6 py-2..3 text-sm|base medium|semibold | F17: rolls own (arbitrary var tokens) | G17: Duplicates .btn-primary with rounded-full instead of rounded-xl.
A18: buttons | B18: Ad-hoc accent small CTA | C18: components/group/WithheldPagePosts.tsx:62; components/browse/WithheldAnnouncementCard.tsx:86; components/RecruitmentGrid.tsx:111,148; app/following/page.tsx:93 | D18: 5 | E18: rounded-lg/rounded-md, px-3 py-1.5 text-xs|[11px] | F18: rolls own | G18: No small size of btn-primary, so each re-invents one.
A19: buttons | B19: AddProductButton / AddServiceButton / AddGatheringButton | C19: components/sell/Add{Product,Service,Gathering}Button.tsx | D19: 1 | E19: btn-secondary trigger + inline neutral-900 toast | F19: recipe + raw palette | G19: Three near-identical files incl. duplicated inline toast.
A20: buttons | B20: AddToCalendarLink | C20: components/calendar/AddToCalendarLink.tsx | D20: 2 | E20: link | F20: tokens
A21: buttons | B21: AuthButton | C21: components/AuthButton.tsx | D21: 0 | E21: btn-primary/btn-secondary | F21: recipe | G21: ORPHAN.
A22: buttons | B22: AuthCtaButtons | C22: components/AuthCtaButtons.tsx | D22: 1 | E22: compact/full | F22: rolls own accent pill | G22: Only used by orphan HomeFeed.
A23: buttons | B23: Charcoal full-width sheet CTA | C23: components/explore/ExploreFilterSheet.tsx:203; components/group/ReportSheet.tsx:166; components/metro/MetroStandingDialog.tsx:87; components/metro/MetroWaitlistStep.tsx:77,138 | D23: 4 | E23: w-full rounded-full bg-charcoal-700 py-3 text-sm semibold white | F23: rolls own | G23: Contradicts globals.css 'Charcoal ... never a CTA fill'.
A24: buttons | B24: FollowButton | C24: components/FollowButton.tsx | D24: 1 | E24: following/not | F24: rolls own (accent var) | G24: Legacy /following only. One of four follow buttons.
A25: buttons | B25: FollowMemberButton | C25: components/member/FollowMemberButton.tsx | D25: 1 | E25: btn-primary/btn-secondary | F25: recipe; error text-red-600 | G25: Near-identical to FollowVenueButton.
A26: buttons | B26: FollowPageButton | C26: components/group/FollowPageButton.tsx | D26: 1 | E26: signin link / toggle | F26: btn-primary + custom | G26: Duplicates Follow{Member,Venue}Button.
A27: buttons | B27: FollowVenueButton | C27: components/venue/FollowVenueButton.tsx | D27: 1 | E27: btn-primary/btn-secondary | F27: recipe; error text-red-600 | G27: Copy of FollowMemberButton.
A28: buttons | B28: Icon button (circle) | C28: components/explore/ExploreSearchBar.tsx:95,105; components/group/ReportSheet.tsx:124; components/explore/ExploreFilterSheet.tsx:134 | D28: 3 | E28: h-11 w-11 vs h-9 w-9 | F28: rolls own; hover:bg-neutral-100 | G28: Modal closes elsewhere are bare p-1 icons (AuthGateModal, AddEntityDrawer, MarketSelector) under 44px.
A29: buttons | B29: ShareLinkButton | C29: components/item/ShareLinkButton.tsx | D29: 1 | E29: btn-secondary | F29: recipe
A30: buttons | B30: SupportButton | C30: components/SupportButton.tsx | D30: 0 | E30: red-50/red-100 toggle | F30: raw palette | G30: ORPHAN.
